Workbook

Sheet 1.Matériel
C7: Locaux de l'entreprise | D7: Systèmes | E7: Matériel | F7: Logiciels
B8: Interne | C8: Atelier de production, bureaux administratifs, salle serveurs, zone de stockage matières premières, réseau invités, extranet/portail web, serveurs mail, ERP, données personnelles | D8: Active Directory | E8: Serveurs physiques | F8: Windows Server 2022
D9: ERP | E9: NAS/stockage | F9: ERP GPL
D10: Messagerie | E10: Switchs/routeurs | F10: Postfix / Dovecot
D11: Sauvegarde centralisée | F11: Veeam
D12: Réseau invités/utilisateurs | E12: VPN accès distant/Firewall | F12: OpenVPN/OpenSense
D13: PKI | E13: Fedora serveur | F13: Dogtag
D14: Stockage matières premières | E14: Hangar, local de rangement
D15: Extranet | E15: Fedora serveur | F15: Fedora ?
D16: Imprimantes/Scanner | E16: Imprimantes/Scanner
D17: Proxy | E17: Serveurs physiques
D18: Reverse Proxy | E18: Serveurs physiques
D19: Bastion | E19: Serveurs physiques | F19: Apache Guacamole
D20: MFA Keyclock | E20: Serveurs physiques
D21: Serveurs de fichiers | E21: Serveurs physiques | F21: Samba
D22: SIEM | E22: Serveurs physiques | F22: Graylog
D23: EPP | E23: Serveurs physiques | F23: ESET
D24: EDR | E24: Serveurs physiques | F24: ESET
D25: Gestionnaire de secrets | E25: Serveurs physiques
D26: Gestionnaire de serveurs | E26: Serveurs physiques | F26: OCS
B27: Externe | C27: Fournisseurs bois/vernis, fournisseurs cloud/DNS, fournisseurs publics, prestataires externes | D27: DNS public | E27: Fedora serveur | F27: Bind9/Unbound
D28: Fournisseurs
D29: Equipement FAI | E29: Box internet, réseau filaire pour les postes de travail?, Nombre d'arrivées de fbres (juste une ligne FTTO, une ligne FTTH en support pour un mode dgradé ou encore une antenne 5G dans le cas ou tout tombe) | F29: Bouygues, OS de la box et des bornes wifi
B34: Source de menace | D34: Exemples
B35: Cybercriminels | D35: Ransomware, phishing
B36: Employés malveillants | D36: Vol, suppression de données
B37: Erreurs humaines | D37: Mauvaise configuration
B38: Malware | D38: Virus, spyware
B39: Attaquant externe | D39: Exploitation web, VPN
B40: Prestataire externe | D40: Accès abusif
B41: Catastrophe naturelle | D41: Incendie, innondation
B42: Panne matérielle | D42: Disque dur HS
B43: Coupure électrique | D43: Arrêt serveurs
B44: Fournisseur défaillant | D44: Rupture matières premières
B45: Fuite d'information | D45: Publication de documents internes
... B48: Obsolescence technique | D48: Windows XP
C50: Organisation | D50: Personnes
B51: Interne | C51: Direction | D51: Président
D52: Directeur général
C53: Production atelier | D53: Chef de Projet
...

Sheet 1.Métriques
A3: Disponibilité | E3: Gravité \Vraisemblance | F3: 1 | G3: 2 | H3: 3 | I3: 4
A4: id | B4: Niveau | C4: Description | E4: 1 | F4: =E4+F3 -> 2 | G4: =E4+G3 -> 3 | H4: =E4+H3 -> 4 | I4: =E4+I3 -> 5
A5: D1 | B5: plus de 48h | C5: La durée d'interuption du bien est superieure à 48h | E5: 2 | F5: =E5+F3 -> 3 | G5: =E5+G3 -> 4 | H5: =E5+H3 -> 5 | I5: =E5+I3 -> 6
A6: D2 | B6: entre 24h et 48h | C6: La durée d'interuption du bien se situe entre 24h et 48h | E6: 3 | F6: =E6+F3 -> 4 | G6: =E6+G3 -> 5 | H6: =E6+H3 -> 6 | I6: =E6+I3 -> 7
A7: D3 | B7: entre 4h et 24h | C7: La durée d'interuption du bien se situe entre 4h et 24h | E7: 4 | F7: =E7+F3 -> 5 | G7: =E7+G3 -> 6 | H7: =E7+H3 -> 7 | I7: =E7+I3 -> 8
A8: D4 | B8: moins de 4h | C8: La durée d'interuption du bien est inférieur à 4h
A11: Intégrité
A12: id | B12: Niveau | C12: Description
A13: I1 | B13: Non intègre | C13: le bien peut ne doit pas etre intègre
A14: I2 | B14: Détéctable | C14: le bien peut ne pas etre intègre, à partir du moment ou l'altération est identifiée
A15: I3 | B15: Maitrisé | C15: le bien peut ne pas etre intègre, à partir du moment ou l'altération est identifiée, et si l'intégrité peut etre retrouvée
A16: I4 | B16: Rigoureusement Intègre | C16: le bien doit etre rigouresement intègre.
A19: Confidentialité
A20: id | B20: Niveau | C20: Description
A21: C1 | B21: Public | C21: Le bien est publique
A22: C2 | B22: Limité | C22: le bien est réservé au personnel et prestataire
A23: C3 | B23: Réservé | C23: le bien est réservé au personnel interne et impliqué
A24: C4 | B24: Privé | C24: le bien est réservé au personnel identifié et ayant le besoins de connaitre le bien
A27: Echelle de gravité
A28: id | B28: Niveau | C28: Description
A29: G1 | B29: Négligeable | C29: X surmonteras les impacts sans difficulté
A30: G2 | B30: Limitée | C30: X surmonteras les impacts malgré quelques difficultés
A31: G3 | B31: Importante | C31: X surmonteras les impacts avec des difficultés sérieuses
A32: G4 | B32: Critique | C32: X ne surmonteras pas les impacts
A35: Echelle de vraisemblance
A36: id | B36: Niveau | C36: Description
A37: V1 | B37: Minime | C37: Très peut probable
A38: V2 | B38: Significative | C38: Pourrait se produire
A39: V3 | B39: Forte | C39: Devrais se produire
A40: V4 | B40: Maximale | C40: Vas très certainement se produire
A43: Capacité de détection d'un évenement redouté
A44: id | B44: Niveau | C44: Description
A45: E1 | B45: Insignifiante | C45: Aucune détection possible pour cet évenement redouté
A46: E2 | B46: Unitaire | C46: Peu de détection possible pour cet évenement redouté
A47: E3 | B47: Multiples | C47: L'évenement est couvert par plusieurs sources de détections
A48: E4 | B48: Couvert | C48: L'évenement doit être détecté et remedié dans 100% des cas
N49: Score du Risque = Gravité (G) × Vraisemblance (V)

Sheet 1.Biens_identifiés
B2: Les missions / Processus Métiers | C2: Processus Essentiels
B3: Gestion RH | C3: Gestion personnel (présence, absence)
C4: Gestion des recrutements
C5: Gestion des contrats/dossiers salariés
B6: Administration et supervision de l'infrastructure | C6: Gestion des incidents et alertes
C7: Gestion des accès utilisateurs (AD)
C8: Maintenance
C9: Mise à jour
C10: Supervision
B11: Prise de commande et relations client | C11: Prise de contact
C12: Devis et configuration des cercueils personnalisés
C13: Validation de commande
C14: Paiement en ligne
B15: Gestion des dossiers d'obsèques et familles | C15: Création des dossiers
C16: Recueil des volontés (personnalisation)
C17: Suivi du dossier client
C18: Archivage des dossiers
C19: Facturation
B20: Gestion financière | C20: Gestion trésorerie et comptes bancaires
C21: Gestion de la paie
C22: Gestion des factures fournisseur
C23: Suivi des achats matières premières
B24: Production | C24: Fabrication des cercueils
C25: Personnalisation (peinture, motifs, design)
C26: Contrôle qualité
C27: Gestion des stocks matières premières
C28: Planification de production
B29: Logistique | C29: Réception des matières premières
C30: Stockage et gestion des stocks
C31: Expédition des cercueils
C32: Suivi des livraisons
B33: Marketing, web, extranet | C33: Gestion du site
C34: Support client en ligne
G35: Gestion RH | J35: Administration et supervision | O35: Prise de commandes et relations client | S35: Gestion des dossiers d'obsèques et familles | X35: Gestion financière | AB35: Production | AG35: Logistique | AK35: Marketing, Web, Extranet
E36: Systèmes | F36: Matériel | G36: Gestion Personnel | H36: Gestion des recrutements | I36: Gestion des contrats/dossiers salariés | J36: Gestion des incidents et alertes | K36: Gestion des accès utilisateurs | L36: Maintenance | M36: Mise à jour | N36: Supervision | O36: Prise de contact | P36: Devis et configuration des cercueils personnalisés | Q36: Validation de commandes | R36: Paiement en ligne | S36: Création des dossiers | T36: Recueil des volontés (personnalisation) | U36: Suivi du dossier client | V36: Archivage des dossiers | W36: Facturation | X36: Gestion trésorerie et comptes bancaires | Y36: Gestion de la paie | Z36: Gestion des factures fournisseur | AA36: Suivi des achats matières premières | AB36: Fabrication des cercueils | AC36: Personnalisation (peinture, motifs, design) | AD36: Contrôle qualité | AE36: Gestion des stocks matières premières | AF36: Planification de production | AG36: Réception des matières premières | AH36: Stockage et gestion des stocks | AI36: Expédition des cercueils | AJ36: Suivi des livraisons | AK36: Gestion du site | AL36: Support client en ligne
E37: Active Directory | F37: Serveurs physiques | G37: x | H37: x | I37: x | J37: x | K37: x | L37: x | M37: x | N37: x | P37: x | Q37: x | S37: x | T37: x | U37: x | V37: x | W37: x | X37: x | Y37: x | Z37: x | AA37: x | AJ37: x | AK37: x | AL37: x
E38: ERP | F38: NAS/stockage | G38: x | H38: x | I38: x | O38: x | P38: x | Q38: x | S38: x | T38: x | U38: x | V38: x | W38: x | X38: x | Y38: x | Z38: x | AA38: x | AB38: x | AC38: x | AD38: x | AE38: x | AF38: x | AG38: x | AH38: x | AI38: x | AJ38: x
E39: Messagerie | F39: Switchs/routeurs | G39: x | H39: x | I39: x | J39: x | N39: x | O39: x | P39: x | Q39: x | T39: x | U39: x | Z39: x | AH39: x | AJ39: x | AL39: x
F40: Serveurs physiques | G40: x | H40: x | I40: x | J40: x | N40: x | O40: x | P40: x | Q40: x | T40: x | U40: x | Z40: x | AH40: x | AJ40: x | AL40: x
E41: Sauvegarde centralisée | F41: Serveurs physiques | G41: x | H41: x | I41: x | J41: x | K41: x | L41: x | M41: x | N41: x | O41: x | P41: x | Q41: x | R41: x | S41: x | T41: x | U41: x | V41: x | W41: x | X41: x | Y41: x | Z41: x | AA41: x | AE41: x | AF41: x | AH41: x | AJ41: x | AK41: x | AL41: x
...

Sheet 2.Evenements_redoutés
G2: Impacts
C3: Les processus essentiels | D3: Evénements redoutés | E3: Besoins de sécurité | F3: Source de menace | G3: Description - Impacts | H3: D | I3: I | J3: C | K3: Gravité
B4: Gestion RH | C4: Gestion du personnel | D4: - Modification, Création, Suppression de données - Partie de l'infra qui ne répond plus (ERP, serveur de fichiers, messagerie, AD, etc.) - Accès non autorisé - Vol d'information | E4: D3, I4, C3 | F4: Hackers, employé interne (qui veut trafiquer son profil), RH/tech incompétent | G4: - Perte d'activité et impact financier, perte de confiance des collaborateurs | H4: X | I4: X | J4: X | K4: Limitée
C5: Gestion des recrutements | D5: - Usurpation d'identité - Infiltration - Vol d'information - Espionnage - Modification, création, suppression de données | E5: D1, I3, C3 | F5: Hackers, RH/tech incompétent | G5: - Problème de suivi des recrutements - Perte de temps - Potentiellement sous-effectif si pas hors service trop longtemps | H5: X | I5: X | J5: X | K5: X
C6: Gestion des contrats/dossiers salariés | D6: - Modification, création, suppression de données, - Vol d'information - Accès non autorisé - Espionnage | E6: D2, I4, C4 | F6: Hackers, employé interne (qui veut trafiquer son profil), RH/tech incompétent | G6: - Problème de contrats/paie - Perte de confiance envers les employés - Ralentissement dû à des contrats incertains | H6: X | I6: X | J6: X | K6: Limitée
B7: Administration et supervision de l'infrastructure | C7: Gestion des incidents et alertes | D7: - Pannes des serveurs - Mauvaise remontée de logs - Alertes mal répertoriées (criticité) | E7: D4, I4, C4 | F7: Hackers, employé interne, panne physique | G7: - Manque de sécurité - Potentiel ravisseur allant jusqu'à la destruction totale de l'infrastructure - Fausse compréhension du problème - Ralentissement de l'activité - Ransomware - Perte financière | H7: X | I7: X | J7: X | K7: Critique
C8: Gestion des accès utilisateurs (AD) | D8: - Permissions mal attribuées - Utilisateurs pas mis à jour - Compromission des données - Accès non autorisé - Vol de credentials | E8: D4, I4, C4 | F8: Hackers, employé interne, panne physique | G8: - Manque de sécurité - Potentiel ravisseur allant jusqu'à la destruction totale de l'infrastructure - Fausse compréhension du problème - Ralentissement de l'activité - Escalade de privilège - Accès non autorisé | H8: X | I8: X | J8: X | K8: Critique
C9: Maintenance | D9: - Backup non opérationnel / non accessible - Outils de sécurité qui ne fonctionnent plus - Serveur web mis hors service - Corruption de services (gestionnaire de secrets, gestionnaires des parc, etc.) - Destruction de l'infrastructure | E9: D3, I4, C4 | F9: Hackers, admin incompétent, employé interne (malveillant ou pas), Malware | G9: Perte d'activité et impact financier, mise en péril de l'infrastructure, perte de confiance des clients | H9: X | I9: X | J9: X | K9: Critique
C10: Mise à jour | D10: - Matériel non mis à jour - Installation d'un malware ou de paquets malveillants | E10: D3, I4, C4 | F10: Hackers, admin incompétent, employé interne (malveillant ou pas), malware | G10: Perte d'activité et impact financier, mise en péril de l'infrastructure, perte de confiance des clients | H10: X | I10: X | J10: X | K10: Critique
C11: Supervision | D11: - Altération ou Suppression des données, logs et de l'infrastructure - Accès non autorisé aux autres services liés | E11: D4, I4, C4 | F11: Hackers, admin incompétent, employé interne (malveillant ou pas), malware, erreur humaine | G11: Perte d'activité et impact financier, mise en péril de l'infrastructure, perte de confiance des clients | H11: X | I11: X | J11: X | K11: Critique
B12: Prise de commande et relations client | C12: Prise de contact | D12: - Interception du contact - Contacter un acteur malveillant - Vol d'identifiants de compte (par le biais de phishing, etc.) - Divulgation de données sensibles | E12: I3, C3 | F12: Client, Hacker, Employé, Infostealer | G12: Impact sur l'activité et la confiance des clients, usurpation d'identité | I12: X | J12: X | K12: Limitée
C13: Devis et configuration des cercueils personnalisés | D13: - Expositions involontaires de données sensibles - Injections de commandes / scripts malveillants - Modification du site (liens malveillants, messages, diffamation, etc.) | E13: D4, I3, C1 | F13: Hacker, équipe tech, employé | G13: Impact sur l'activité, la réputation et la confiance des clients | H13: X | I13: X | J13: X | K13: Importante
C14: Validation de commande | D14: - Commandes disparues - Commandes faux positives | E14: D3, I3, C2 | F14: Hacker, erreur humaine | G14: - Mauvais suivi des commandes - Pertes financières | K14: Négligeable
C15: Paiement en ligne | D15: - Mauvaise redirection - Paiement effectué au mauvais destinataire - Paiement jamais reçu - Montant invalide - Vol d'informations carte bleue | E15: D2, I4, C2 | F15: Client, Hacker, Infostealer, erreur humaine | G15: Impact sur les transactions, confiance client | H15: X | I15: X | J15: X | K15: Importante
B16: Gestion des dossiers obsèques et familles | C16: Création des dossiers | D16: - Création de faux dossiers clients - Altération des dossiers clients (modification / Suppression) - Accès non autorisé aux dossiers clients - Vol de données | E16: I2, C3 | F16: Hacker, erreur humaine | G16: Confiance des clients, usurpation d'identité, réputation, confidentialité | I16: X | J16: X | K16: Limitée
C17: Recueil des volontés | D17: - Modification, fausses ou suppression des volontés | E17: D2, I3, C3 | F17: Hacker, erreur humaine | G17: Confiance client | H17: X | I17: X | J17: X | K17: Négligeable
C18: Suivi du dossier client | D18: - Altération des dossiers clients (modification / Suppression) - Accès non autorisé aux dossiers clients - Vol de données | E18: D3, I3, C2 | F18: Hacker, erreur humaine | G18: - Perte de confiance du client - Impact sur l'activité | H18: X | I18: X | J18: X | K18: Limitée
C19: Archivage des dossiers | D19: - Création de faux dossiers clients - Altération des dossiers clients (modification / Suppression) - Accès non autorisé aux dossiers clients - Vol de données - Mauvais archivage (archivage de dossiers en cours) | E19: D1, I3, C2 | F19: Hacker, erreur humaine | G19: - Incompréhension employé interne - Impossibilité de s'appuyer sur l'expérience - Ralentissement de l'activité | H19: X | I19: X | J19: X | K19: Limitée
C20: Facturation | D20: - Fausses factures reçues / émises - Vol de données - Faux / mauvais destinataire | E20: I4, C4 | F20: Hacker, erreur humaine, infostealer | G20: Impact sur les transactions, confiance client | I20: X | J20: X | K20: Importante
B21: Gestion financière | C21: Gestion trésorerie et comptes bancaires | D21: - Modification des comptes - Vol d'identifiants - Vol d'argent - Réception de faux documents de trésorerie - Dépenses non prévues / justifiées | E21: D4, I4, C4 | F21: Hacker, erreur humaine, malware, infostealer, employé malveillant | G21: Impact sur la trésorerie | H21: X | I21: X | J21: X | K21: Critique
C22: Gestion de la paie | D22: - Paie au mauvais destinataire - Paie envoyé au mauvais moment - Paie donnée avec un mauvais montant - Accès non autorisé aux données sensibles (bulletins de paie) | E22: D2, I4, C4 | F22: Hacker, erreur humaine, employé malveillant | G22: Impact sur la trésorerie et sur la confiance des collaborateurs | H22: X | I22: X | J22: X | K22: Importante
C23: Gestion des factures / achats | D23: - Accès non autorisé aux factures, achats - Réception de faux documents de trésorerie | E23: D3, I3, C3 | F23: Hacker, erreur humaine, employé malveillant | G23: Impact sur la trésorerie | H23: X | I23: X | J23: X | K23: Importante
C24: Suivi des achats matières premières | D24: - Mauvaise entrée de données - Achats réalisé en retard - Mauvais suivi des achats | E24: D3, I2, C2 | F24: Hacker, erreur humaine, panne | G24: - Incompréhension employé interne - Perte de traçabilité - Ralentissement de l'activité - Perte confiance fournisseurs | H24: X | I24: X | J24: X | K24: Négligeable
B25: Production | C25: Fabrication des cercueils | D25: - Retard sur les achats - Retard sur la fabrication (fournisseurs) - Employés en sous-effectif - Arrêt des machines | E25: C2 | F25: Hacker, erreur humaine, panne | G25: - Perte confiance clients (attente du client) - Impact financier et sur l'activité | J25: X | K25: Limitée
C26: Personnalisation (peinture, motifs, design) | D26: - Retard sur les achats - Retard sur la personnalisation - Employés en sous-effectif - Arrêt des machines - Personnalisation indisponible | E26: C2 | F26: Hacker, erreur humaine, panne | G26: - Perte confiance clients (attente du client) - Impact financier et sur l'activité | J26: X | K26: Limitée
C27: Contrôle qualité | D27: - Employés en sous-effectif - Retard sur le contrôle qualité - Serveur de fichier en panne | E27: D2, I4, C2 | F27: Erreur humaine | G27: - Incompréhension employé interne - Perte de traçabilité - Ralentissement de l'activité - Manque de validation | H27: X | I27: X | J27: X | K27: Limitée
C28: Gestion des stocks matières premières | D28: - Mauvais jugement sur les stocks - Erreur d'achats, fournisseurs - Problèmes sur la qualité | E28: I4, C3 | F28: Erreur humaine | G28: - Perte confiance clients (attente du client) - Impact financier et sur l'activité - Perte confiance fournisseur | I28: X | J28: X | K28: Limitée
C29: Planification de production | D29: - Mauvaise plannification - Employé en sous-effectif | E29: C2 | F29: Erreur humaine | G29: - Impact sur l'activité - Perte confiance fournisseur + client | J29: X | K29: Limitée
B30: Logistique | C30: Réception des matières premières | D30: - Mauvaise coordination sur la réception - Manque de personnel - Dossier incomplet - Mauvaise prévision - Date repoussé | E30: D3, C2 | F30: Hacker, erreur humaine, panne | G30: - Impact sur l'activité - Perte confiance fournisseur + client - Impact sur la traçabilité | H30: X | J30: X | K30: Limitée
C31: Stockage et gestion des stocks | D31: - Mauvaise prévision - Dossier incomplet - Inventaire faussé/pas fait - Non accès à la base de données de l'inventaire | E31: D2, I4, C3 | F31: Hacker, erreur humaine, panne | G31: - Impact sur l'activité - Perte confiance fournisseur + client - Impact sur la traçabilité - Perte confiance des employés | H31: X | I31: X | J31: X | K31: Limitée
C32: Expédition des cercueils | D32: - Manque de personnel - Retard sur l'expédition (traffic, externe) - Système HS (ERP) | E32: D3, C2 | F32: Hacker, erreur humaine, panne | G32: - Impact sur l'activité - Perte confiance fournisseur + client - Impact sur la traçabilité | H32: X | J32: X | K32: Limitée
C33: Suivi des livraisons | D33: - Mauvaise traçabilité - Retard sur l'expédition (traffic, externe) - Système HS (ERP) | E33: D3, C2 | F33: Hacker, erreur humaine, panne | G33: - Impact sur l'activité - Perte confiance fournisseur + client - Impact sur la traçabilité | H33: X | J33: X | K33: Limitée
B34: Marketing, web, extranet | C34: Gestion du site | D34: - Manque de personnel - Trop de tâches en même temps - Site qui ne fonctionne plus - Site qui est piraté | E34: D4, I4, C3 | F34: Hacker, erreur technique, panne | G34: - Ralentissement de l'activité - Perte de clients - Impossibilité de travailler pour les employés - Perte d'activité | H34: X | I34: X | J34: X | K34: Critique
C35: Support client en ligne | D35: - Manque de personnel - Trop de tâches en même temps - Site qui ne fonctionne plus - Site qui est piraté | E35: D4, C3 | F35: Hacker, erreur technique, panne | G35: - Ralentissement de l'activité - Perte de clients - Perte d'activité | H35: X | J35: X | K35: Critique

Sheet 2.Synthèse
B2: Gravité | C2: Evénement
B3: Négligeable | C3: {=_xlfn.TEXTJOIN(CHAR(10), TRUE, _xlfn._xlws.FILTER(Event[Evénements redoutés],Event[Gravité]="Négligeable "))} -> - Commandes disparues - Commandes faux positives - Modification, fausses ou suppression des volontés - Mauvaise entrée de données - Achats réalisé en retard - Mauvais suivi des achats
B4: Limitée | C4: {=_xlfn.TEXTJOIN(CHAR(10), TRUE, _xlfn._xlws.FILTER(Event[Evénements redoutés],Event[Gravité]="Limitée"))} -> - Modification, Création, Suppression de données - Partie de l'infra qui ne répond plus (ERP, serveur de fichiers, messagerie, AD, etc.) - Accès non autorisé - Vol d'information - Modification, création, suppression de données, - Vol d'information - Accès non autorisé - Espionnage - Interception du contact - Contacter un acteur malveillant - Vol d'identifiants de compte (par le biais de phishing, etc.) - Divulgation de données sensibles - Création de faux dossiers clients - Altération des dossiers clients (modification / Suppression) - Accès non autorisé aux dossiers clients - Vol de données - Altération des dossiers clients (modification / Suppression) - Accès non autorisé aux dossiers clients - Vol de données - Création de faux dossiers clients - Altération des dossiers clients (modification / Suppression) - Accès non autorisé aux dossiers clients - Vol de données - Mauvais archivage (archivage de dossiers en cours) - Retard sur les achats - Retard sur la fabrication (fournisseurs) - Employés en sous-effectif - Arrêt des machines - Retard sur les achats - Retard sur la personnalisation - Employés en sous-effectif - Arrêt des machines - Personnalisation indisponible - Employés en sous-effectif - Retard sur le contrôle qualité - Serveur de fichier en panne - Mauvais jugement sur les stocks - Erreur d'achats, fournisseurs - Problèmes sur la qualité - Mauvaise plannification - Employé en sous-effectif - Mauvaise coordination sur la réception - Manque de personnel - Dossier incomplet - Mauvaise prévision - Date repoussé - Mauvaise prévision - Dossier incomplet - Inventaire faussé/pas fait - Non accès à la base de données de l'inventaire - Manque de personnel - Retard sur l'expédition (traffic, externe) - Système HS (ERP) - Mauvaise traçabilité - Retard sur l'expédition (traffic, externe) - Système HS (ERP)
B5: Important | C5: {=_xlfn.TEXTJOIN(CHAR(10), TRUE, _xlfn._xlws.FILTER(Event[Evénements redoutés],Event[Gravité]="Importante"))} -> - Expositions involontaires de données sensibles - Injections de commandes / scripts malveillants - Modification du site (liens malveillants, messages, diffamation, etc.) - Mauvaise redirection - Paiement effectué au mauvais destinataire - Paiement jamais reçu - Montant invalide - Vol d'informations carte bleue - Fausses factures reçues / émises - Vol de données - Faux / mauvais destinataire - Paie au mauvais destinataire - Paie envoyé au mauvais moment - Paie donnée avec un mauvais montant - Accès non autorisé aux données sensibles (bulletins de paie) - Accès non autorisé aux factures, achats - Réception de faux documents de trésorerie
B6: Critique | C6: {=_xlfn.TEXTJOIN(CHAR(10), TRUE, _xlfn._xlws.FILTER(Event[Evénements redoutés],Event[Gravité]="Critique"))} -> - Pannes des serveurs - Mauvaise remontée de logs - Alertes mal répertoriées (criticité) - Permissions mal attribuées - Utilisateurs pas mis à jour - Compromission des données - Accès non autorisé - Vol de credentials - Backup non opérationnel / non accessible - Outils de sécurité qui ne fonctionnent plus - Serveur web mis hors service - Corruption de services (gestionnaire de secrets, gestionnaires des parc, etc.) - Destruction de l'infrastructure - Matériel non mis à jour - Installation d'un malware ou de paquets malveillants - Altération ou Suppression des données, logs et de l'infrastructure - Accès non autorisé aux autres services liés - Modification des comptes - Vol d'identifiants - Vol d'argent - Réception de faux documents de trésorerie - Dépenses non prévues / justifiées - Manque de personnel - Trop de tâches en même temps - Site qui ne fonctionne plus - Site qui est piraté - Manque de personnel - Trop de tâches en même temps - Site qui ne fonctionne plus - Site qui est piraté

Sheet 3.Scénario_de_menaces
C2: Scénarios de menaces | D2: Sources de menaces | E2: Vraisemblance
B3: Serveur de fichiers | C3: Création, modification, suppression non désirable de fichiers sur le Serveur de fichiers | D3: Erreur humaine interne, Hacker | E3: Maximale
C4: Synchronisation incorrecte entre serveurs de fichiers | D4: Erreur de réplication / mauvaise config | E4: Forte
C5: Corruption des fichiers suite à panne disque RAID | D5: Panne matérielle / vieillissement | E5: Forte
C6: Suppression accidentelle d’un dossier client par un employé | D6: Erreur humaine interne | E6: Maximale
C7: Chiffrement des fichiers du Serveur de fichiers suite à une infection ransomware | D7: Malware / phishing / attaque technique | E7: Significative
C9: Indisponibilité du serveur de fichiers | D9: Malware/attaque technique/erreur humaine interne | E9: Forte
C10: Mauvaise gestion des permissions / accès sur les dossiers partagés (serveur de fichiers) | D10: Erreur humaine interne, négligence | E10: Forte
B11: VPN | C11: Compromission de credentials VPN | D11: Hacking/Fuite de credentials | E11: Forte
C12: Endpoint avec accès VPN compromis | D12: Hacking, vol de PC, infection par un virus | E12: Significative
C13: Profils VPN / routage VPN trop permissifs | D13: Erreur humaine interne, négligence | E13: Significative
B14: Les Serveurs DNS | C14: Serveurs DNS (resolveurs ou authoritaires) en panne | D14: Hacker, problème technique | E14: Significative
C15: Enregistrements DNS publics invalides | D15: Mauvaise configuration / mauvaise maintenance | E15: Minime
C16: Attaque par Déni de service ciblant notre serveur DNS authoritaire | D16: Hacker | E16: Forte
C17: Compromission de serveurs DNS | D17: Hacker/menace interne | E17: Significative
C18: Altération de nos enregistrements DNS par un tiers | D18: Attaquant externe | E18: Significative
C19: Transferts de zone DNS non autorisés (AXFR mal configuré) | D19: Attaquant externe | E19: Significative
C20: Mauvaise gestion des clés DNSSEC (perte, le vol, expiration...) | D20: Mauvaise configuration/Hacker | E20: Significative
B21: Bastion | C21: Accès non autorisé au bastion | D21: Malware/Hacker/menace interne/backdoor | E21: Forte
C22: Compromission du bastion (et donc de toute l'infra) | D22: Malware/Hacker | E22: Significative
C23: Manque de durcissement du Bastion | D23: Mauvaise configuration/Hacker | E23: Minime
C24: Bastion en panne | D24: Hacker, problème technique | E24: Significative
C25: Contournement du bastion pour l'accès au machines de prod | D25: Interne | E25: Maximale
C26: Mauvaise surveillance des sessions admin ouvertes depuis le bastion | D26: Interne | E26: Significative
B27: Active Directory | C27: Comptes AD / accès non désactivés après départ d'un employé | D27: Employé/erreur humaine interne | E27: Maximale
C28: Panne / indisponibilité des DCs | D28: Malware/Hacker/Problème réseau | E28: Minime
C29: Compromission d'un DC | D29: Malware/Hacker/problème physique | E29: Minime
C30: Chiffrement de l'AD suite à une infection ransomware | D30: Malware / phishing / attaque technique | E30: Minime
C31: Partage excéssif / réutilisation des mots dee passe Admin | D31: Employé/erreur humaine interne | E31: Maximale
C32: Modification/accès non autorisé à l'AD | D32: Malware/attaque technique/erreur humaine interne/Hacker | E32: Significative
C33: Mauvaise politique de logs dans l'AD (perte de logs, évènements non journalisés...) | D33: Mauvaise configuration | E33: Significative
C34: Problèmes de réplication ou erreurs de configuration de la bdd Active Directory | D34: Employé/erreur humaine interne / Mauvaise configuration | E34: Minime
C35: Risques liés à la sauvegarde et à la restauration des DCs | D35: Employé/erreur humaine interne / Mauvaise configuration | E35: Maximale
C36: Mauvaise gestion des droits / accès dans l'AD | D36: Employé/erreur humaine interne / Mauvaise configuration | E36: Forte
B37: Firewalls interne & externe | C37: Perte d'accès au firewall (administration) | D37: Mauvaise configuration | E37: Minime
C38: Firewall exposant son interface d'administration | D38: Mauvaise configuration/Hacker | E38: Significative
C39: Attaque DDOS ciblant le firewall | D39: Hacker | E39: Maximale
C40: Firewall en panne/ne fonctionnant pas | D40: Mauvaise configuration/Hacker | E40: Significative
C41: Exposition involontaire des sous-réseaux sur internet | D41: Mauvaise configuration | E41: Minime
C42: Création de règles firewall mal configurées / trop permissives | D42: Mauvaise configuration/Hacker | E42: Forte
...

Sheet 3.Synthèse
B2: Vraisemblance | C2: Scénarios de menaces
B3: Maximale | C3: {=_xlfn.TEXTJOIN(CHAR(10), TRUE, _xlfn._xlws.FILTER(menaces[[Scénarios de menaces ]],menaces[Vraisemblance]="Maximale"))} -> Création, modification, suppression non désirable de fichiers sur le Serveur de fichiers Suppression accidentelle d’un dossier client par un employé Contournement du bastion pour l'accès au machines de prod Comptes AD / accès non désactivés après départ d'un employé Partage excéssif / réutilisation des mots dee passe Admin Risques liés à la sauvegarde et à la restauration des DCs Attaque DDOS ciblant le firewall Shadow IT sur le firewall / surabondance de règles firewall Attaque par déni de service ciblant le serveur Web Fraude au président par un tier malveillant Phishing sur les employés Spoofing (usurpation) de notre domaine mail Pas de SSO pour lire / envoyer des mails Pas de redondance du stockage des backups Certificat expiré et non renouvelé Mots de passe trop faibles / non renouvelés Accès non autorisé par un tier aux Postes Windows / Linux Accès direct aux ports (USB notamment) et interfaces internes des machines Configurations faibles et exploitables car manque de hardening sur les machines Accès physique aux données du disque dur car non chiffré Installation d'applications non autorisées sur les postes utilisateurs
B4: Forte | C4: {=_xlfn.TEXTJOIN(CHAR(10), TRUE, _xlfn._xlws.FILTER(menaces[[Scénarios de menaces ]],menaces[Vraisemblance]="Forte"))} -> Synchronisation incorrecte entre serveurs de fichiers Corruption des fichiers suite à panne disque RAID Indisponibilité du serveur de fichiers Mauvaise gestion des permissions / accès sur les dossiers partagés (serveur de fichiers) Compromission de credentials VPN Attaque par Déni de service ciblant notre serveur DNS authoritaire Accès non autorisé au bastion Mauvaise gestion des droits / accès dans l'AD Création de règles firewall mal configurées / trop permissives Mauvaise visibilité / mauvais logging du traffic réseau sur le firewall Défacement du site web vitrine mauvaise isolation des services sur le serveur Web (NGINX, bdd…) anti‑spam/anti‑malware mal configuré (faux positifs ou passage de messages dangereux) Plugin / add-on client mail (MUA) vulnérable Backups automatiques non réalisées Corruption des backups / backups incohérentes (backups de bases de données notamment) Génération indésirable / malveillante de certificats Mauvais suivi / documentation / gestion des changements de configuration du parc conflits entre playbooks de configuration et changements manuels sur les serveurs du parc Accès / gestion des droits trop permissive sur le Coffre-Fort Mots de passes stockés en clair hors du Coffre fort Mauvaise remontée de logs Escalade de privilèges sur Postes Windows / Linux Modification/suppression des données depuis les postes Windows / Linux Installation et exécution d'un virus sur un Poste utilisateur Accès physique et exploitation du mode recovery des machines
B5: Significative | C5: {=_xlfn.TEXTJOIN(CHAR(10), TRUE, _xlfn._xlws.FILTER(menaces[[Scénarios de menaces ]],menaces[Vraisemblance]="Significative"))} -> Chiffrement des fichiers du Serveur de fichiers suite à une infection ransomware Endpoint avec accès VPN compromis Profils VPN / routage VPN trop permissifs Serveurs DNS (resolveurs ou authoritaires) en panne Compromission de serveurs DNS Altération de nos enregistrements DNS par un tiers Transferts de zone DNS non autorisés (AXFR mal configuré) Mauvaise gestion des clés DNSSEC (perte, le vol, expiration...) Compromission du bastion (et donc de toute l'infra) Bastion en panne Mauvaise surveillance des sessions admin ouvertes depuis le bastion Modification/accès non autorisé à l'AD Mauvaise politique de logs dans l'AD (perte de logs, évènements non journalisés...) Firewall exposant son interface d'administration Firewall en panne/ne fonctionnant pas Injections de requêtes (XSS…) mauvaise gestion des patchs / mises à jour sur le serveur Web Vol de la base de données de notre site Web Serveurs mails en panne Vol / détournement d'adresse mail / de compte avec email Compromission d'un/des serveurs de mails Altération (Man-in-the-middle) de nos mails en transit (corps ou en-têtes) Manque de contrôle / visibilité dans le cas d'un cleint mail (MUA) sur smartphone Serveur de backup en panne Backups non isolées du réseau et / ou non immuables Manque de stockage pour les backups CA intermédiaire compromise Serveur de publication des certificats (CA Intermédiaire) en panne Vol de la base de données des certificats CRL expirée ou indisponible Serveur de gestion du parc (linux/Windows) compromis Accès non autorisé au serveur de gestion du parc (linux/Windows) par un tiers Serveur de gestion du parc (linux/Windows) non accessible Vol de secrets stockés en clair dans le fichiers de configuration du parc Serveur ERP non accessible Modification frauduleuse des données financières Perte des données internes stockées sur l'ERP (vol, chiffrement, corruption…) Mauvaise gestion de la base de données de l'ERP (complexification, ralentissement…) Données métier sensibles non chiffrées sur l'ERP Boycott / employés n'utilisant pas l'ERP Boycott (ou évitement) du Coffre-Fort par les employés Pas de backup du Coffre-Fort Echec de restauration d'une backup du coffre fort Suppression de logs SIEM/EDR/EPP déconnectés du réseau Règles Proxy mal définies Mauvais routage Proxy Règles Reverse Proxy mal définies Mauvais routage (Reverse Proxy) Exploitation de failles/CVE/zero-day surles Postes utilisateurs Abus des comptes Admin local sur les Postes utilisateurs Postes Utilisateurs / applications sur les postes non mis à jour Navigateurs web non sécurisés sur les Postes utilisateurs Intrusion et vol de matériel informatique
B6: Minime | C6: {=_xlfn.TEXTJOIN(CHAR(10), TRUE, _xlfn._xlws.FILTER(menaces[[Scénarios de menaces ]],menaces[Vraisemblance]="Minime"))} -> Enregistrements DNS publics invalides Manque de durcissement du Bastion Panne / indisponibilité des DCs Compromission d'un DC Chiffrement de l'AD suite à une infection ransomware Problèmes de réplication ou erreurs de configuration de la bdd Active Directory Perte d'accès au firewall (administration) Exposition involontaire des sous-réseaux sur internet Mauvaise segmentation des VLANs Exposition de données sensibles sur le site web Serveur web utilisé comme rebond pour accéder à l'infrastructure en interne (RODC, bdd…) Pas de chiffrement des secrets lors de la récupération des mails (authentification) Pas de chiffrement des mails (au repos ou en transit, sur tous les serveurs) Mauvais patching des clients mail (MUA) Compromission / accès illégitime au serveur de backup Compromission / accès illégitime au compte de service utilisé pour les backups CA Racine compromise Chiffrement des certificats cassé Perte ou corruption des clés racine Détournement des comptes de service utilisés par Ansible Accès non désirable à l'ERP Accès non autorisé au gestionnaire de secrets (Coffre-Fort) Compromission du Coffre-Fort (= compromission des secrets de toute l'infra) Perte des clés de chiffrement du Coffre-Fort Accès non autorisé au SIEM Exposition accidentelle d’une app interne (Reverse Proxy) Attaque applicative par rebond (Reverse Proxy) Abus d'une segmentation faible entre les LANs pour Postes utilisateurs et le reste de l'infra Intrusion et destruction de matériel informatique Incendies dans les locaux de l'entreprise Dégâts des eaux/inondations Sabotage ou destruction accidentelle de l'alimentation électrique/fibre

Sheet 4.Mesure_de_sécurité
B3: Thèmes | C3: Mesure de sécurité | D3: Bien support | E3: Prévention | F3: Protection | G3: Récupération
B4: Audit & traçabilité | C4: Politique de conservation des journaux + collecte légale des preuves post-incident | D4: Journaux systèmes, disques de logs, SIEM | E4: x | F4: x | G4: x
B5: Authentification & gestion des identifiants | C5: MFA + intégration Active Directory + politique de mot de passe robuste + SSO | D5: Active Directory, serveurs d'authentification | E5: x | F5: x
B6: Chiffrement | C6: Chiffrement des données sensibles (AES) + chiffrement des communications | D6: PKI interne, certificats, VPN | E6: x | F6: x
B7: Classification des données | C7: Étiquetage des données (public / interne / confidentiel) + contrôle des accès selon niveau | D7: ERP, serveurs de fichiers | E7: x | F7: x
B8: Continuité / reprise d’activité | C8: Plan de reprise (PRA) + redondance serveurs + sauvegardes externalisées | D8: Serveurs backup, cloud/offsite | E8: x | F8: x | G8: x
B9: Contrôle d’accès | C9: Gestion des droits RBAC + restrictions par groupes AD | D9: Active Directory, ERP, fichiers | E9: x | F9: x
B10: Contrôle des applications | C10: Whitelisting applications + contrôle des scripts + restriction Windows XP | D10: Postes clients, antivirus, EDR | E10: x | F10: x
B11: Gestion des fournisseurs | C11: Contrats de sécurité + contrôle des accès prestataires + comptes temporaires | D11: VPN, accès externes, AD | E11: x | F11: x
B12: Organisation & gouvernance | C12: Politique de sécurité SI + gestion des habilitations + procédures incident | D12: SIEM, documentation SI | E12: x
B13: Politique poste de travail / sensibilisation | C13: USB contrôlées + sensibilisation phishing + verrouillage session automatique | D13: Postes utilisateurs, périphériques amovibles | E13: x | F13: x | G13: x
B14: Protection des données | C14: DLP (Data Loss Prevention) + restriction exfiltration + chiffrement stockage | D14: Serveurs fichiers, messagerie | E14: x | F14: x
B15: Sauvegarde | C15: Sauvegardes automatiques quotidiennes + copies hors ligne + tests de restauration | D15: Serveurs backup, NAS | E15: x | F15: x | G15: x
B16: Segmentation du réseau | C16: VLAN (production / admin / invité / DMZ) + firewall inter-zones | D16: Firewalls, switches, routeurs | E16: x | F16: x
B17: Surveillance & détection | C17: SIEM + IDS/IPS + alertes comportementales (logs AD, VPN, web) | D17: SIEM, logs centralisés | E17: x | F17: x | G17: x
B18: Surveillance physique de l'infrastructure | C18: Extincteur + local serveur ventilé + locaux de l'entreprise verrouillés + deuxième ligne de fibre + antenne 5G | D18: Extincteurs, système de ventilation, serrure et verrous électroniques
B19: Surveillance environnementale | C19: Deuxième ligne de fibre + antenne 5G | D19: Lignes de fibres (FTTO/FTTH), antenne 5G

Sheet 4.Mesure_de_détection
B2: Lien Mitre Att&ch enterprise techniques : | C2: https://attack.mitre.org/techniques/enterprise/
B4: Thèmes | C4: Mesure de détection | D4: Bien support | E4: Tactique MITRE | F4: Technique MITRE
B5: Authentification AD | C5: Détection brute force + alertes login anormaux | D5: Active Directory / SIEM | E5: Credential Access | F5: Brute Force (T1110)
B6: Authentification AD | C6: Détection connexion hors horaires / pays inhabituels | D6: AD / VPN logs | E6: Initial Access | F6: Valid Accounts (T1078)
B7: VPN | C7: Alertes accès VPN suspects / multi-échecs | D7: VPN / Firewall | E7: Initial Access | F7: Brute Force (T1110)
B8: VPN | C8: Détection session détournée | D8: VPN gateway | E8: Credential Access | F8: Session Hijacking (T1563)
B9: Serveur de fichiers | C9: Détection suppression massive de fichiers | D9: File server / SIEM | E9: Impact | F9: Data Destruction (T1485)
B10: Serveur de fichiers | C10: Alertes modification permissions anormales | D10: AD / file audit logs | E10: Privilege Escalation | F10: Permission Groups Discovery (T1069)
B11: Ransomware | C11: Détection chiffrement massif fichiers | D11: EDR / antivirus | E11: Impact | F11: Data Encrypted for Impact (T1486)
B12: Active Directory | C12: Détection création comptes admin | D12: AD audit logs | E12: Persistence | F12: Account Manipulation (T1098)
B13: Active Directory | C13: Détection modifications GPO | D13: AD / SIEM | E13: Persistence | F13: Group Policy Modification (T1484)
B14: Firewall | C14: Détection scan ports / trafic anormal | D14: Firewall / IDS | E14: Discovery | F14: Network Service Scanning (T1046)
B15: Firewall | C15: Détection règles modifiées | D15: Firewall logs | E15: Defense Evasion | F15: Modify System Firewall (T1562.004)
... B33: Poste utilisateur | C33: Détection USB suspect | D33: EDR / endpoint policy | E33: Initial Access | F33: Removable Media (T1091)
B34: Réseau / connectivité | C34: Déection de la charge sur le réseau et de son interruption | D34: Routeur / Parefeu
B35: Sécurité physique | C35: Détection d'intrusion | D35: Alarme
B36: Environnement / Matériel | C36: Détection de fumée ou température de la pièce | D36: Détecteur de fumée / Thermomètre
B37: Environnement / Energie | C37: Détection de la perte d'alimentation et passage sur onduleur avant éteingnege des machines | D37: Onduleur

Sheet 4.risques
B1: Evènements | G1: Menace | J1: Mesure de sécurité | O1: Prise en compte des mesures de sécurité | Q1: Mesure de détection
A2: ID | B2: Evénements redoutés | C2: Besoins de sécurité | D2: Source du risque | E2: Impacts | F2: Gravité | G2: Scénario de menace | H2: Source de menace | I2: Vraisemblance | J2: Mesure de sécurité existante | K2: Bien support | L2: Prévention | M2: Protection | N2: Récupération | O2: Réévaluation de l'impact | P2: Réévaluation de la vraisemblance | Q2: Mesure de détection existante | R2: Capacité en mesure de détection
A3: 1 | B3: Perte ou altération de données | F3: Critique | G3: =menaces[[#This Row],[Scénarios de menaces ]] -> Création, modification, suppression non désirable de fichiers sur le Serveur de fichiers | H3: =menaces[[#This Row],[Sources de menaces]] -> Erreur humaine interne, Hacker | I3: =menaces[[#This Row],[Vraisemblance]] -> Maximale | J3: Sauvegardes / ACL strictes / MFA / versioning / revue des droits | O3: Limitée | P3: Significative | Q3: SIEM sur accès fichiers / alertes suppression massive / logs NTFS | R3: Multiples
A4: =A3+1 -> 2 | B4: Données incohérentes ou indisponibles | F4: Importante | G4: =menaces[[#This Row],[Scénarios de menaces ]] -> Synchronisation incorrecte entre serveurs de fichiers | H4: =menaces[[#This Row],[Sources de menaces]] -> Erreur de réplication / mauvaise config | I4: =menaces[[#This Row],[Vraisemblance]] -> Forte | J4: Supervision réplication / tests réguliers / procédures de rollback | O4: Limitée | P4: Minime | Q4: Monitoring réplication / alertes latence / contrôle intégrité | R4: Multiples
A5: =A4+1 -> 3 | B5: Perte définitive de données | F5: Critique | G5: =menaces[[#This Row],[Scénarios de menaces ]] -> Corruption des fichiers suite à panne disque RAID | H5: =menaces[[#This Row],[Sources de menaces]] -> Panne matérielle / vieillissement | I5: =menaces[[#This Row],[Vraisemblance]] -> Forte | J5: RAID renforcé / disques hot‑spare / monitoring matériel / PRA | K5: Importante | L5: Minime | M5: Alertes SMART / supervision RAID / détection erreurs I/O | N5: Multiples | O5: Importante | P5: Minime | Q5: Supervision RAID / détection erreurs I/O | R5: Multiples
A6: =A5+1 -> 4 | B6: Perte de données métier essentielles | F6: Importante | G6: =menaces[[#This Row],[Scénarios de menaces ]] -> Suppression accidentelle d’un dossier client par un employé | H6: =menaces[[#This Row],[Sources de menaces]] -> Erreur humaine interne | I6: =menaces[[#This Row],[Vraisemblance]] -> Maximale | J6: Recycle bin / versioning / sauvegardes fréquentes / restrictions d’accès | K6: Limitée | L6: Significative | M6: Alertes suppression volumétrique / journalisation accès | N6: Unitaire | O6: Limitée | P6: Significative | Q6: Alertes suppression volumétrique / journalisation accès | R6: Unitaire
A7: =A6+1 -> 5 | B7: Indisponibilité totale des données + risque d’extorsion | F7: Critique | G7: =menaces[[#This Row],[Scénarios de menaces ]] -> Chiffrement des fichiers du Serveur de fichiers suite à une infection ransomware | H7: =menaces[[#This Row],[Sources de menaces]] -> Malware / phishing / attaque technique | I7: =menaces[[#This Row],[Vraisemblance]] -> Significative | J7: EDR / segmentation / sauvegardes immuables / filtrage mail / durcissement postes | O7: Critique | P7: Minime | Q7: Détection comportementale EDR / alertes chiffrement massif | R7: Couvert
A8: 6
A9: =A8+1 -> 7 | B9: Arrêt complet de l’activité dépendante des données | F9: Critique | G9: =menaces[[#This Row],[Scénarios de menaces ]] -> Indisponibilité du serveur de fichiers | H9: =menaces[[#This Row],[Sources de menaces]] -> Malware/attaque technique/erreur humaine interne | I9: =menaces[[#This Row],[Vraisemblance]] -> Forte | J9: Redondance stockage / cluster / supervision disponibilité | O9: Critique | P9: Minime | Q9: Monitoring disponibilité / alertes latence / tests automatiques | R9: Multiples
A10: =A9+1 -> 8 | B10: Exposition ou modification non autorisée de données | F10: Importante | G10: =menaces[[#This Row],[Scénarios de menaces ]] -> Mauvaise gestion des permissions / accès sur les dossiers partagés (serveur de fichiers) | H10: =menaces[[#This Row],[Sources de menaces]] -> Erreur humaine interne, négligence | I10: =menaces[[#This Row],[Vraisemblance]] -> Forte | J10: Revue régulière des droits / IAM / RBAC | O10: Limitée | P10: Minime | Q10: Audit permissions / alertes SIEM accès anormaux | R10: Multiples
A11: =A10+1 -> 9 | B11: Intrusion dans le SI et accès aux données internes | F11: Critique | G11: =menaces[[#This Row],[Scénarios de menaces ]] -> Compromission de credentials VPN | H11: =menaces[[#This Row],[Sources de menaces]] -> Hacking/Fuite de credentials | I11: =menaces[[#This Row],[Vraisemblance]] -> Forte | J11: MFA (authentification AD + certificats) | O11: Critique | P11: Significative | Q11: journalisation des connexions / alertes SIEM basées sur les attributs (localisation de l'employé, heure…) | R11: Unitaire
A12: =A11+1 -> 10 | B12: Intrusion dans le SI et accès aux données internes | F12: Critique | G12: =menaces[[#This Row],[Scénarios de menaces ]] -> Endpoint avec accès VPN compromis | H12: =menaces[[#This Row],[Sources de menaces]] -> Hacking, vol de PC, infection par un virus | I12: =menaces[[#This Row],[Vraisemblance]] -> Significative | J12: Durcissement des postes utilisateurs / révocation des tokens d'authentification VPN | O12: Critique | P12: Significative | Q12: journalisation des connexions / alerte manuelle des utilisateurs dn cas de vol | R12: Unitaire
A13: =A12+1 -> 11 | B13: Utilisation malveillante d’un service interne | F13: Importante | G13: =menaces[[#This Row],[Scénarios de menaces ]] -> Profils VPN / routage VPN trop permissifs | H13: =menaces[[#This Row],[Sources de menaces]] -> Erreur humaine interne, négligence | I13: =menaces[[#This Row],[Vraisemblance]] -> Significative | J13: Durcissement services / cloisonnement | O13: Importante | P13: Minime | Q13: SIEM / détection usage anormal / logs applicatifs | R13: Multiples
A14: =A13+1 -> 12 | B14: Perte d’accès aux services internes/externe | F14: Importante | G14: =menaces[[#This Row],[Scénarios de menaces ]] -> Serveurs DNS (resolveurs ou authoritaires) en panne | H14: =menaces[[#This Row],[Sources de menaces]] -> Hacker, problème technique | I14: =menaces[[#This Row],[Vraisemblance]] -> Significative | J14: Redondance DNS / supervision / anycast / PRA | O14: Importante | P14: Minime | Q14: Monitoring disponibilité DNS / alertes latence | R14: Unitaire
A15: =A14+1 -> 13 | B15: Interruption de service ou fraude | F15: Importante | G15: =menaces[[#This Row],[Scénarios de menaces ]] -> Enregistrements DNS publics invalides | H15: =menaces[[#This Row],[Sources de menaces]] -> Mauvaise configuration / mauvaise maintenance | I15: =menaces[[#This Row],[Vraisemblance]] -> Minime | J15: DNSSEC / durcissement serveurs DNS / contrôle des zones | O15: Limitée | P15: Minime | Q15: Analyse logs DNS / détection anomalies requêtes | R15: Unitaire
A16: =A15+1 -> 14 | B16: Perte de résolution externe | F16: Importante | G16: =menaces[[#This Row],[Scénarios de menaces ]] -> Attaque par Déni de service ciblant notre serveur DNS authoritaire | H16: =menaces[[#This Row],[Sources de menaces]] -> Hacker | I16: =menaces[[#This Row],[Vraisemblance]] -> Forte | J16: Redondance / supervision réseau / ban IP firewall | O16: Importante | P16: Significative | Q16: Monitoring connectivité / alertes perte de liaison | R16: Multiples
A17: =A16+1 -> 15 | B17: Détournement massif du trafic | F17: Critique | G17: =menaces[[#This Row],[Scénarios de menaces ]] -> Compromission de serveurs DNS | H17: =menaces[[#This Row],[Sources de menaces]] -> Hacker/menace interne | I17: =menaces[[#This Row],[Vraisemblance]] -> Significative | J17: durcissement / accès restreints / MFA admin / segmentation | O17: Critique | P17: Forte | Q17: SIEM DNS / détection modification zones / alertes admin | R17: Multiples
A18: =A17+1 -> 16 | B18: Redirection vers sites malveillants | F18: Critique | G18: =menaces[[#This Row],[Scénarios de menaces ]] -> Altération de nos enregistrements DNS par un tiers | H18: =menaces[[#This Row],[Sources de menaces]] -> Attaquant externe | I18: =menaces[[#This Row],[Vraisemblance]] -> Significative | J18: DNSSEC / validation réponses / durcissement résolveurs | O18: Critique | P18: Minime | Q18: Détection incohérences DNS / logs résolveurs | R18: Unitaire
A19: =A18+1 -> 17 | B19: Exposition de la structure interne du SI | F19: Importante | G19: =menaces[[#This Row],[Scénarios de menaces ]] -> Transferts de zone DNS non autorisés (AXFR mal configuré) | H19: =menaces[[#This Row],[Sources de menaces]] -> Attaquant externe | I19: =menaces[[#This Row],[Vraisemblance]] -> Significative | J19: Restriction AXFR / IP allow‑list / DNSSEC / durcissement serveurs DNS | O19: Importante | P19: Minime | Q19: Logs DNS / alertes requêtes AXFR dans le SIEM | R19: Unitaire
A20: =A19+1 -> 18 | B20: Perte de confiance dans le DNS | F20: Critique | G20: =menaces[[#This Row],[Scénarios de menaces ]] -> Mauvaise gestion des clés DNSSEC (perte, le vol, expiration...) | H20: =menaces[[#This Row],[Sources de menaces]] -> Mauvaise configuration/Hacker | I20: =menaces[[#This Row],[Vraisemblance]] -> Significative | J20: rotation clés / procédures de gestion | O20: Critique | P20: Minime | Q20: Alertes expiration clés / logs signature | R20: Unitaire
... A37: =A36+1 -> 35 | B37: Perte de contrôle du périmètre | F37: Importante | G37: =menaces[[#This Row],[Scénarios de menaces ]] -> Perte d'accès au firewall (administration) | H37: =menaces[[#This Row],[Sources de menaces]] -> Mauvaise configuration | I37: =menaces[[#This Row],[Vraisemblance]] -> Minime | J37: Redondance firewall / comptes d’urgence / segmentation / durcissement | O37: Importante | P37: Minime | Q37: Monitoring disponibilité / alertes changement config | R37: Unitaire
A38: =A37+1 -> 36 | B38: Intrusion dans le SI | F38: Critique | G38: =menaces[[#This Row],[Scénarios de menaces ]] -> Firewall exposant son interface d'administration | H38: =menaces[[#This Row],[Sources de menaces]] -> Mauvaise configuration/Hacker | I38: =menaces[[#This Row],[Vraisemblance]] -> Significative | J38: IPS/IDS / durcissement règles / revue régulière / segmentation / MFA admin | K38: Critique | L38: Minime | M38: SIEM / détection scans / alertes intrusion / logs firewall | N38: Multiples | O38: Critique | P38: Minime | Q38: SIEM / détection scans / alertes intrusion / logs firewall | R38: Multiples
A39: =A38+1 -> 37 | B39: Indisponibilité des services exposés | F39: Critique | G39: =menaces[[#This Row],[Scénarios de menaces ]] -> Attaque DDOS ciblant le firewall | H39: =menaces[[#This Row],[Sources de menaces]] -> Hacker | I39: =menaces[[#This Row],[Vraisemblance]] -> Maximale | J39: Anti‑DDoS / CDN / filtrage / redondance liens / scrubbing center | O39: Critique | P39: Significative | Q39: Monitoring volumétrie / alertes saturation / analyse trafic | R39: Multiples
A40: =A39+1 -> 38 | B40: Perte de protection périmétrique | F40: Critique | G40: =menaces[[#This Row],[Scénarios de menaces ]] -> Firewall en panne/ne fonctionnant pas | H40: =menaces[[#This Row],[Sources de menaces]] -> Mauvaise configuration/Hacker | I40: =menaces[[#This Row],[Vraisemblance]] -> Significative | J40: Redondance HA / PRA / supervision / maintenance proactive | O40: Critique | P40: Minime | Q40: Monitoring disponibilité / alertes bascule cluster | R40: Unitaire
A41: =A40+1 -> 39 | B41: Accès non autorisé | F41: Importante | G41: =menaces[[#This Row],[Scénarios de menaces ]] -> Exposition involontaire des sous-réseaux sur internet | H41: =menaces[[#This Row],[Sources de menaces]] -> Mauvaise configuration | I41: =menaces[[#This Row],[Vraisemblance]] -> Minime | J41: Revue règles / segmentation / automatisation déploiement / validation config | O41: Importante | P41: Minime | Q41: Scan exposition / SIEM / alertes ouverture ports | R41: Multiples
A42: =A41+1 -> 40 | B42: Ouverture de failles critiques | F42: Importante | G42: =menaces[[#This Row],[Scénarios de menaces ]] -> Création de règles firewall mal configurées / trop permissives | H42: =menaces[[#This Row],[Sources de menaces]] -> Mauvaise configuration/Hacker | I42: =menaces[[#This Row],[Vraisemblance]] -> Forte | J42: Revue par pairs / automatisation / CI‑CD infra / segmentation | O42: Importante | P42: Minime | Q42: Alertes modification règles / audit config / SIEM | R42: Multiples
A43: =A42+1 -> 41 | B43: Accès non autorisé au réseau interne | F43: Importante | G43: =menaces[[#This Row],[Scénarios de menaces ]] -> Mauvaise segmentation des VLANs | H43: =menaces[[#This Row],[Sources de menaces]] -> Employé/erreur humaine interne / Mauvaise configuration | I43: =menaces[[#This Row],[Vraisemblance]] -> Minime | J43: Segmentation stricte / firewall interne / NAC / micro‑segmentation | O43: Importante | P43: Minime | Q43: SIEM / détection flux interdits | R43: Multiples
A44: =A43+1 -> 42 | B44: Ouverture de failles réseau | F44: Importante | G44: =menaces[[#This Row],[Scénarios de menaces ]] -> Shadow IT sur le firewall / surabondance de règles firewall | H44: =menaces[[#This Row],[Sources de menaces]] -> Employé/erreur humaine interne / Mauvaise configuration | I44: =menaces[[#This Row],[Vraisemblance]] -> Maximale | J44: Gouvernance / revue règles / CI‑CD | O44: Importante | P44: Forte | Q44: Audit règles | R44: Unitaire
A45: =A44+1 -> 43 | B45: Absence de surveillance réseau | F45: Importante | G45: =menaces[[#This Row],[Scénarios de menaces ]] -> Mauvaise visibilité / mauvais logging du traffic réseau sur le firewall | H45: =menaces[[#This Row],[Sources de menaces]] -> Employé/erreur humaine interne / Mauvaise configuration | I45: =menaces[[#This Row],[Vraisemblance]] -> Forte | J45: Activation logs / centralisation | O45: Importante | P45: Minime | Q45: Monitoring flux | R45: Unitaire
A46: =A45+1 -> 44 | B46: Défiguration / perte d’image | F46: Limitée | G46: =menaces[[#This Row],[Scénarios de menaces ]] -> Défacement du site web vitrine | H46: =menaces[[#This Row],[Sources de menaces]] -> Hacker | I46: =menaces[[#This Row],[Vraisemblance]] -> Forte | J46: WAF / durcissement serveur / CI‑CD sécurisé / contrôle intégrité / patching | O46: Limitée | P46: Minime | Q46: Monitoring intégrité fichiers / SIEM / alertes modification contenu | R46: Multiples
A47: =A46+1 -> 45 | B47: Fuite de données | F47: Critique | G47: =menaces[[#This Row],[Scénarios de menaces ]] -> Exposition de données sensibles sur le site web | H47: =menaces[[#This Row],[Sources de menaces]] -> Mauvaise administration/Hacking/Scraping | I47: =menaces[[#This Row],[Vraisemblance]] -> Minime | J47: Scan vulnérabilités / durcissement API / chiffrement / revue code / WAF | O47: Critique | P47: Minime | Q47: Scan exposition / alertes fuite données / SIEM | R47: Multiples
A48: =A47+1 -> 46 | B48: Compromission de l’application | F48: Critique | G48: =menaces[[#This Row],[Scénarios de menaces ]] -> Injections de requêtes (XSS…) | H48: =menaces[[#This Row],[Sources de menaces]] -> Acteur malveillant | I48: =menaces[[#This Row],[Vraisemblance]] -> Significative | J48: WAF / validation entrées / ORM / revue code / patching / segmentation | O48: Critique | P48: Minime | Q48: WAF signatures / détection patterns injection / logs applicatifs | R48: Couvert
A49: =A48+1 -> 47 | B49: Intrusion dans le SI | F49: Critique | G49: =menaces[[#This Row],[Scénarios de menaces ]] -> Serveur web utilisé comme rebond pour accéder à l'infrastructure en interne (RODC, bdd…) | H49: =menaces[[#This Row],[Sources de menaces]] -> Hacker | I49: =menaces[[#This Row],[Vraisemblance]] -> Minime | J49: Segmentation / WAF / durcissement / EDR / patching | O49: Critique | P49: Minime | Q49: SIEM / détection mouvements latéraux / logs web | R49: Multiples
A50: =A49+1 -> 48 | B50: Intrusion dans les services internes | F50: Critique | G50: =menaces[[#This Row],[Scénarios de menaces ]] -> mauvaise isolation des services sur le serveur Web (NGINX, bdd…) | H50: =menaces[[#This Row],[Sources de menaces]] -> Employé/erreur humaine interne / Mauvaise configuration | I50: =menaces[[#This Row],[Vraisemblance]] -> Forte | J50: Segmentation / durcissement / comptes dédiés / WAF | O50: Importante | P50: Significative | Q50: Logs web / WAF | R50: Multiples
... A58: =A57+1 -> 56 | B58: Accès aux communications sensibles | F58: Critique | G58: =menaces[[#This Row],[Scénarios de menaces ]] -> Compromission d'un/des serveurs de mails | H58: =menaces[[#This Row],[Sources de menaces]] -> Hacker/Malware | I58: =menaces[[#This Row],[Vraisemblance]] -> Significative | J58: Segmentation / durcissement / EDR / patching / accès restreints | O58: Critique | P58: Minime | Q58: Logs mail / alertes exfiltration / EDR | R58: Multiples
A59: =A58+1 -> 57 | B59: Usurpation d’identité de l’entreprise | F59: Critique | G59: =menaces[[#This Row],[Scénarios de menaces ]] -> Spoofing (usurpation) de notre domaine mail | H59: =menaces[[#This Row],[Sources de menaces]] -> Hacker | I59: =menaces[[#This Row],[Vraisemblance]] -> Maximale | J59: SPF / DKIM / DMARC / anti‑spoofing | O59: Critique | P59: Minime | R59: Insignifiante
